<?xml version="1.0" encoding="utf-8"?>
<!-- =================================================================================== -->
<!-- |    This document was autogenerated by xacro from hexapod_body.xacro             | -->
<!-- |    EDITING THIS FILE BY HAND IS NOT RECOMMENDED                                 | -->
<!-- =================================================================================== -->
<robot name="hexapod">
  <!-- ros_control plugin -->
  <gazebo>
    <plugin filename="libgazebo_ros_control.so" name="gazebo_ros_control">
      <robotNamespace>/hexapod</robotNamespace>
      <robotSimType>gazebo_ros_control/DefaultRobotHWSim</robotSimType>
    </plugin>
  </gazebo>
  <!-- Definin g link colours for Gazebo -->
  <!-- base_link -->
  <gazebo reference="base_link">
    <material>Gazebo/Orange</material>
    <selfCollide>true</selfCollide>
    <turnGravityOff>0</turnGravityOff>
  </gazebo>
  <!-- leg1_coxa -->
  <gazebo reference="leg1_coxa">
    <material>Gazebo/Red</material>
    <selfCollide>true</selfCollide>
    <turnGravityOff>0</turnGravityOff>
  </gazebo>
  <!-- leg2_coxa -->
  <gazebo reference="leg2_coxa">
    <material>Gazebo/Red</material>
    <selfCollide>true</selfCollide>
    <turnGravityOff>0</turnGravityOff>
  </gazebo>
  <!-- leg3_coxa -->
  <gazebo reference="leg3_coxa">
    <material>Gazebo/Red</material>
    <selfCollide>true</selfCollide>
    <turnGravityOff>0</turnGravityOff>
  </gazebo>
  <!-- leg4_coxa -->
  <gazebo reference="leg4_coxa">
    <material>Gazebo/Red</material>
    <selfCollide>true</selfCollide>
    <turnGravityOff>0</turnGravityOff>
  </gazebo>
  <!-- leg5_coxa -->
  <gazebo reference="leg5_coxa">
    <material>Gazebo/Red</material>
    <selfCollide>true</selfCollide>
    <turnGravityOff>0</turnGravityOff>
  </gazebo>
  <!-- leg6_coxa -->
  <gazebo reference="leg6_coxa">
    <material>Gazebo/Red</material>
    <selfCollide>true</selfCollide>
    <turnGravityOff>0</turnGravityOff>
  </gazebo>
  <!-- leg1_femur -->
  <gazebo reference="leg1_femur">
    <material>Gazebo/White</material>
    <selfCollide>true</selfCollide>
    <turnGravityOff>0</turnGravityOff>
  </gazebo>
  <!-- leg2_femur -->
  <gazebo reference="leg2_femur">
    <material>Gazebo/White</material>
    <selfCollide>true</selfCollide>
    <turnGravityOff>0</turnGravityOff>
  </gazebo>
  <!-- leg3_femur -->
  <gazebo reference="leg3_femur">
    <material>Gazebo/White</material>
    <selfCollide>true</selfCollide>
    <turnGravityOff>0</turnGravityOff>
  </gazebo>
  <!-- leg4_femur -->
  <gazebo reference="leg4_femur">
    <material>Gazebo/White</material>
    <selfCollide>true</selfCollide>
    <turnGravityOff>0</turnGravityOff>
  </gazebo>
  <!-- leg5_femur -->
  <gazebo reference="leg6_femur">
    <material>Gazebo/White</material>
    <selfCollide>true</selfCollide>
    <turnGravityOff>0</turnGravityOff>
  </gazebo>
  <!-- leg6_femur -->
  <gazebo reference="leg6_femur">
    <material>Gazebo/White</material>
    <selfCollide>true</selfCollide>
    <turnGravityOff>0</turnGravityOff>
  </gazebo>
  <!-- leg1_tibia -->
  <gazebo reference="leg1_tibia">
    <material>Gazebo/Blue</material>
    <selfCollide>true</selfCollide>
    <turnGravityOff>0</turnGravityOff>
  </gazebo>
  <!-- leg2_tibia -->
  <gazebo reference="leg2_tibia">
    <material>Gazebo/Blue</material>
    <turnGravityOff>0</turnGravityOff>
    <selfCollide>true</selfCollide>
  </gazebo>
  <!-- leg3_tibia -->
  <gazebo reference="leg3_tibia">
    <material>Gazebo/Blue</material>
    <selfCollide>true</selfCollide>
    <turnGravityOff>0</turnGravityOff>
  </gazebo>
  <!-- leg4_tibia -->
  <gazebo reference="leg4_tibia">
    <material>Gazebo/Blue</material>
    <selfCollide>true</selfCollide>
    <turnGravityOff>0</turnGravityOff>
  </gazebo>
  <!-- leg5_tibia -->
  <gazebo reference="leg5_tibia">
    <material>Gazebo/Blue</material>
    <selfCollide>true</selfCollide>
    <turnGravityOff>0</turnGravityOff>
  </gazebo>
  <!-- leg6_tibia -->
  <gazebo reference="leg6_tibia">
    <material>Gazebo/Blue</material>
    <selfCollide>true</selfCollide>
    <turnGravityOff>0</turnGravityOff>
  </gazebo>
  <!-- leg1_rubber_tip -->
  <gazebo reference="leg1_rubber_tip">
    <material>Gazebo/Black</material>
    <selfCollide>true</selfCollide>
    <turnGravityOff>0</turnGravityOff>
  </gazebo>
  <!-- leg2_rubber_tip -->
  <gazebo reference="leg2_rubber_tip">
    <material>Gazebo/Black</material>
    <selfCollide>true</selfCollide>
    <turnGravityOff>0</turnGravityOff>
  </gazebo>
  <!-- leg3_rubber_tip -->
  <gazebo reference="leg3_rubber_tip">
    <material>Gazebo/Black</material>
    <selfCollide>true</selfCollide>
    <turnGravityOff>0</turnGravityOff>
  </gazebo>
  <!-- leg4_rubber_tip -->
  <gazebo reference="leg4_rubber_tip">
    <material>Gazebo/Black</material>
    <selfCollide>true</selfCollide>
    <turnGravityOff>0</turnGravityOff>
  </gazebo>
  <!-- leg5_rubber_tip -->
  <gazebo reference="leg5_rubber_tip">
    <material>Gazebo/Black</material>
    <selfCollide>true</selfCollide>
    <turnGravityOff>0</turnGravityOff>
  </gazebo>
  <!-- leg6_rubber_tip -->
  <gazebo reference="leg6_rubber_tip">
    <material>Gazebo/Black</material>
    <selfCollide>true</selfCollide>
    <turnGravityOff>0</turnGravityOff>
  </gazebo>
  <!-- leg1_rubber_tip -->
  <!--
   <gazebo reference="leg1_tibia__leg1_rubber_tip">
    <preserveFixedJoint>true</preserveFixedJoint>
  </gazebo>

     <gazebo reference="leg2_tibia__leg2_rubber_tip">
    <preserveFixedJoint>true</preserveFixedJoint>
  </gazebo>

     <gazebo reference="leg3_tibia__leg3_rubber_tip">
    <preserveFixedJoint>true</preserveFixedJoint>
  </gazebo>

     <gazebo reference="leg4_tibia__leg4_rubber_tip">
    <preserveFixedJoint>true</preserveFixedJoint>
  </gazebo>

     <gazebo reference="leg5_tibia__leg5_rubber_tip">
    <preserveFixedJoint>true</preserveFixedJoint>
  </gazebo>

     <gazebo reference="leg6_tibia__leg6_rubber_tip">
    <preserveFixedJoint>true</preserveFixedJoint>
  </gazebo>
-->
  <material name="black">
    <color rgba="0.0 0.0 0.0 1.0"/>
  </material>
  <material name="blue">
    <color rgba="0.0 0.0 0.8 1.0"/>
  </material>
  <material name="green">
    <color rgba="0.0 0.8 0.0 1.0"/>
  </material>
  <material name="grey">
    <color rgba="0.2 0.2 0.2 1.0"/>
  </material>
  <material name="orange">
    <color rgba="1.0 0.423529411765 0.0392156862745 1.0"/>
  </material>
  <material name="brown">
    <color rgba="0.870588235294 0.811764705882 0.764705882353 1.0"/>
  </material>
  <material name="red">
    <color rgba="0.8 0.0 0.0 1.0"/>
  </material>
  <material name="white">
    <color rgba="1.0 1.0 1.0 1.0"/>
  </material>
  <!-- Used for fixing robot to Gazebo 'base_link' -->
  <link name="base_dummy"/>
  <joint name="fixed_joint" type="fixed">
    <parent link="base_dummy"/>
    <child link="base_link"/>
    <origin rpy="0 0 0" xyz="0 0 0"/>
  </joint>
  <link name="base_link">
    <collision>
      <origin rpy="0 0 0" xyz="0 0 0"/>
      <geometry>
        <mesh filename="package://hexapod_description/meshes/base_link_collision.stl" scale="0.001 0.001 0.001"/>
      </geometry>
    </collision>
    <visual>
      <origin rpy="0 0 0" xyz="0 0 0"/>
      <geometry>
        <mesh filename="package://hexapod_description/meshes/base_link.stl" scale="0.001 0.001 0.001"/>
      </geometry>
      <material name="red"/>
    </visual>
    <inertial>
      <origin rpy="0 0 0" xyz="0 0 0.021"/>
      <mass value="1.3"/>
      <inertia ixx="5.404e-3" ixy="0" ixz="0" iyx="0" iyy="3.169e-3" iyz="0" izx="0" izy="0" izz="8.191e-3"/>
    </inertial>
  </link>
  <joint name="base_link__leg1_coxa" type="revolute">
    <axis xyz="0 0 1"/>
    <limit effort="2.8" lower="-1.5708" upper="1.5708" velocity="5.6548668"/>
    <origin rpy="0 3.14159 -0.7854" xyz="0.072981 0.109608 0.021"/>
    <parent link="base_link"/>
    <child link="leg1_coxa"/>
  </joint>
  <link name="leg1_coxa">
    <collision>
      <origin rpy="0 3.14159 0" xyz="0 0 0"/>
      <geometry>
        <mesh filename="package://hexapod_description/meshes/leg_coxa_collision.stl" scale="0.001 0.001 0.001"/>
      </geometry>
    </collision>
    <visual>
      <origin rpy="0 3.14159 0" xyz="0 0 0"/>
      <geometry>
        <mesh filename="package://hexapod_description/meshes/leg_coxa.stl" scale="0.001 0.001 0.001"/>
      </geometry>
      <material name="red"/>
    </visual>
    <inertial>
      <origin rpy="0 3.14159 0" xyz="0 0.023937 0"/>
      <mass value="0.04"/>
      <inertia ixx="1.605e-5" ixy="-5.7988e-8" ixz="0" iyx="-5.7988e-8" iyy="2.012e-5" iyz="5.7639e-8" izx="0" izy="5.7639e-8" izz="1.605e-5"/>
    </inertial>
  </link>
  <joint name="leg1_coxa__leg1_femur" type="revolute">
    <axis xyz="0 0 1"/>
    <limit effort="2.8" lower="-1.5708" upper="1.5708" velocity="5.6548668"/>
    <origin rpy="-1.5708 0 1.5708" xyz="0 0.047868 0"/>
    <parent link="leg1_coxa"/>
    <child link="leg1_femur"/>
  </joint>
  <link name="leg1_femur">
    <collision>
      <origin rpy="-1.5708 0 0" xyz="0.0385 0 0"/>
      <geometry>
        <mesh filename="package://hexapod_description/meshes/leg_femur_collision.stl" scale="0.001 0.001 0.001"/>
      </geometry>
    </collision>
    <visual>
      <origin rpy="-1.5708 0 0" xyz="0.0385 0 0"/>
      <geometry>
        <mesh filename="package://hexapod_description/meshes/leg_femur.stl" scale="0.001 0.001 0.001"/>
      </geometry>
      <material name="red"/>
    </visual>
    <inertial>
      <origin rpy="0 0 1.5708" xyz="0.0385 0 0"/>
      <mass value="0.12"/>
      <inertia ixx="1.005e-4" ixy="0" ixz="0" iyx="0" iyy="2.532e-5" iyz="0" izx="0" izy="0" izz="1.071e-4"/>
    </inertial>
  </link>
  <joint name="leg1_femur__leg1_tibia" type="revolute">
    <axis xyz="0 0 1"/>
    <limit effort="2.8" lower="-1.5708" upper="1.5708" velocity="5.6548668"/>
    <origin rpy="0 0 0" xyz="0.077 0 0"/>
    <parent link="leg1_femur"/>
    <child link="leg1_tibia"/>
  </joint>
  <link name="leg1_tibia">
    <collision>
      <origin rpy="1.5708 0 0" xyz="0 0 0"/>
      <geometry>
        <mesh filename="package://hexapod_description/meshes/leg_tibia_collision.stl" scale="0.001 0.001 0.001"/>
      </geometry>
    </collision>
    <visual>
      <origin rpy="1.5708 0 0" xyz="0 0 0"/>
      <geometry>
        <mesh filename="package://hexapod_description/meshes/leg_tibia.stl" scale="0.001 0.001 0.001"/>
      </geometry>
      <material name="red"/>
    </visual>
    <inertial>
      <origin rpy="1.5708 0 0" xyz="0.077796 -0.036156 0"/>
      <mass value="0.098"/>
      <inertia ixx="1.515e-4" ixy="1.52255e-7" ixz="-9.144e-5" iyx="1.52255e-7" iyy="2.328e-4" iyz="7.0753e-8" izx="-9.144e-5" izy="7.0753e-8" izz="1.159e-4"/>
    </inertial>
  </link>
  <joint name="leg1_tibia__leg1_rubber_tip" type="fixed">
    <parent link="leg1_tibia"/>
    <child link="leg1_rubber_tip"/>
  </joint>
  <link name="leg1_rubber_tip">
    <collision>
      <origin rpy="1.5708 0 0.3769938" xyz="0.136283 -0.133814 0"/>
      <geometry>
        <mesh filename="package://hexapod_description/meshes/leg_rubber_tip.stl" scale="0.001 0.001 0.001"/>
      </geometry>
    </collision>
    <visual>
      <origin rpy="1.5708 0 0.3769938" xyz="0.136283 -0.133814 0"/>
      <geometry>
        <mesh filename="package://hexapod_description/meshes/leg_rubber_tip.stl" scale="0.001 0.001 0.001"/>
      </geometry>
      <material name="red"/>
    </visual>
    <inertial>
      <origin rpy="1.5708 0 0.3769938" xyz="0.136283 -0.133814 0"/>
      <mass value="0.002"/>
      <inertia ixx="1.00584e-7" ixy="0" ixz="0" iyx="0" iyy="1.00579e-7" iyz="0" izx="0" izy="0" izz="1.05103e-7"/>
    </inertial>
  </link>
  <joint name="base_link__leg2_coxa" type="revolute">
    <axis xyz="0 0 1"/>
    <limit effort="2.8" lower="-1.5708" upper="1.5708" velocity="5.6548668"/>
    <origin rpy="0 3.14159 0.7854" xyz="-0.072981 0.109608 0.021"/>
    <parent link="base_link"/>
    <child link="leg2_coxa"/>
  </joint>
  <link name="leg2_coxa">
    <collision>
      <origin rpy="0 3.14159 0" xyz="0 0 0"/>
      <geometry>
        <mesh filename="package://hexapod_description/meshes/leg_coxa_collision.stl" scale="0.001 0.001 0.001"/>
      </geometry>
    </collision>
    <visual>
      <origin rpy="0 3.14159 0" xyz="0 0 0"/>
      <geometry>
        <mesh filename="package://hexapod_description/meshes/leg_coxa.stl" scale="0.001 0.001 0.001"/>
      </geometry>
      <material name="red"/>
    </visual>
    <inertial>
      <origin rpy="0 3.14159 0" xyz="0 0.023937 0"/>
      <mass value="0.04"/>
      <inertia ixx="1.605e-5" ixy="-5.7988e-8" ixz="0" iyx="-5.7988e-8" iyy="2.012e-5" iyz="5.7639e-8" izx="0" izy="5.7639e-8" izz="1.605e-5"/>
    </inertial>
  </link>
  <joint name="leg2_coxa__leg2_femur" type="revolute">
    <axis xyz="0 0 1"/>
    <limit effort="2.8" lower="-1.5708" upper="1.5708" velocity="5.6548668"/>
    <origin rpy="-1.5708 0 1.5708" xyz="0 0.047868 0"/>
    <parent link="leg2_coxa"/>
    <child link="leg2_femur"/>
  </joint>
  <link name="leg2_femur">
    <collision>
      <origin rpy="-1.5708 0 0" xyz="0.0385 0 0"/>
      <geometry>
        <mesh filename="package://hexapod_description/meshes/leg_femur_collision.stl" scale="0.001 0.001 0.001"/>
      </geometry>
    </collision>
    <visual>
      <origin rpy="-1.5708 0 0" xyz="0.0385 0 0"/>
      <geometry>
        <mesh filename="package://hexapod_description/meshes/leg_femur.stl" scale="0.001 0.001 0.001"/>
      </geometry>
      <material name="red"/>
    </visual>
    <inertial>
      <origin rpy="0 0 1.5708" xyz="0.0385 0 0"/>
      <mass value="0.12"/>
      <inertia ixx="1.005e-4" ixy="0" ixz="0" iyx="0" iyy="2.532e-5" iyz="0" izx="0" izy="0" izz="1.071e-4"/>
    </inertial>
  </link>
  <joint name="leg2_femur__leg2_tibia" type="revolute">
    <axis xyz="0 0 1"/>
    <limit effort="2.8" lower="-1.5708" upper="1.5708" velocity="5.6548668"/>
    <origin rpy="0 0 0" xyz="0.077 0 0"/>
    <parent link="leg2_femur"/>
    <child link="leg2_tibia"/>
  </joint>
  <link name="leg2_tibia">
    <collision>
      <origin rpy="1.5708 0 0" xyz="0 0 0"/>
      <geometry>
        <mesh filename="package://hexapod_description/meshes/leg_tibia_collision.stl" scale="0.001 0.001 0.001"/>
      </geometry>
    </collision>
    <visual>
      <origin rpy="1.5708 0 0" xyz="0 0 0"/>
      <geometry>
        <mesh filename="package://hexapod_description/meshes/leg_tibia.stl" scale="0.001 0.001 0.001"/>
      </geometry>
      <material name="red"/>
    </visual>
    <inertial>
      <origin rpy="1.5708 0 0" xyz="0.077796 -0.036156 0"/>
      <mass value="0.098"/>
      <inertia ixx="1.515e-4" ixy="1.52255e-7" ixz="-9.144e-5" iyx="1.52255e-7" iyy="2.328e-4" iyz="7.0753e-8" izx="-9.144e-5" izy="7.0753e-8" izz="1.159e-4"/>
    </inertial>
  </link>
  <joint name="leg2_tibia__leg2_rubber_tip" type="fixed">
    <parent link="leg2_tibia"/>
    <child link="leg2_rubber_tip"/>
  </joint>
  <link name="leg2_rubber_tip">
    <collision>
      <origin rpy="1.5708 0 0.3769938" xyz="0.136283 -0.133814 0"/>
      <geometry>
        <mesh filename="package://hexapod_description/meshes/leg_rubber_tip.stl" scale="0.001 0.001 0.001"/>
      </geometry>
    </collision>
    <visual>
      <origin rpy="1.5708 0 0.3769938" xyz="0.136283 -0.133814 0"/>
      <geometry>
        <mesh filename="package://hexapod_description/meshes/leg_rubber_tip.stl" scale="0.001 0.001 0.001"/>
      </geometry>
      <material name="red"/>
    </visual>
    <inertial>
      <origin rpy="1.5708 0 0.3769938" xyz="0.136283 -0.133814 0"/>
      <mass value="0.002"/>
      <inertia ixx="1.00584e-7" ixy="0" ixz="0" iyx="0" iyy="1.00579e-7" iyz="0" izx="0" izy="0" izz="1.05103e-7"/>
    </inertial>
  </link>
  <joint name="base_link__leg3_coxa" type="revolute">
    <axis xyz="0 0 1"/>
    <limit effort="2.8" lower="-1.5708" upper="1.5708" velocity="5.6548668"/>
    <origin rpy="0 3.14159 -1.5708" xyz="0.09850 0 0.021"/>
    <parent link="base_link"/>
    <child link="leg3_coxa"/>
  </joint>
  <link name="leg3_coxa">
    <collision>
      <origin rpy="0 3.14159 0" xyz="0 0 0"/>
      <geometry>
        <mesh filename="package://hexapod_description/meshes/leg_coxa_collision.stl" scale="0.001 0.001 0.001"/>
      </geometry>
    </collision>
    <visual>
      <origin rpy="0 3.14159 0" xyz="0 0 0"/>
      <geometry>
        <mesh filename="package://hexapod_description/meshes/leg_coxa.stl" scale="0.001 0.001 0.001"/>
      </geometry>
      <material name="red"/>
    </visual>
    <inertial>
      <origin rpy="0 3.14159 0" xyz="0 0.023937 0"/>
      <mass value="0.04"/>
      <inertia ixx="1.605e-5" ixy="-5.7988e-8" ixz="0" iyx="-5.7988e-8" iyy="2.012e-5" iyz="5.7639e-8" izx="0" izy="5.7639e-8" izz="1.605e-5"/>
    </inertial>
  </link>
  <joint name="leg3_coxa__leg3_femur" type="revolute">
    <axis xyz="0 0 1"/>
    <limit effort="2.8" lower="-1.5708" upper="1.5708" velocity="5.6548668"/>
    <origin rpy="-1.5708 0 1.5708" xyz="0 0.047868 0"/>
    <parent link="leg3_coxa"/>
    <child link="leg3_femur"/>
  </joint>
  <link name="leg3_femur">
    <collision>
      <origin rpy="-1.5708 0 0" xyz="0.0385 0 0"/>
      <geometry>
        <mesh filename="package://hexapod_description/meshes/leg_femur_collision.stl" scale="0.001 0.001 0.001"/>
      </geometry>
    </collision>
    <visual>
      <origin rpy="-1.5708 0 0" xyz="0.0385 0 0"/>
      <geometry>
        <mesh filename="package://hexapod_description/meshes/leg_femur.stl" scale="0.001 0.001 0.001"/>
      </geometry>
      <material name="red"/>
    </visual>
    <inertial>
      <origin rpy="0 0 1.5708" xyz="0.0385 0 0"/>
      <mass value="0.12"/>
      <inertia ixx="1.005e-4" ixy="0" ixz="0" iyx="0" iyy="2.532e-5" iyz="0" izx="0" izy="0" izz="1.071e-4"/>
    </inertial>
  </link>
  <joint name="leg3_femur__leg3_tibia" type="revolute">
    <axis xyz="0 0 1"/>
    <limit effort="2.8" lower="-1.5708" upper="1.5708" velocity="5.6548668"/>
    <origin rpy="0 0 0" xyz="0.077 0 0"/>
    <parent link="leg3_femur"/>
    <child link="leg3_tibia"/>
  </joint>
  <link name="leg3_tibia">
    <collision>
      <origin rpy="1.5708 0 0" xyz="0 0 0"/>
      <geometry>
        <mesh filename="package://hexapod_description/meshes/leg_tibia_collision.stl" scale="0.001 0.001 0.001"/>
      </geometry>
    </collision>
    <visual>
      <origin rpy="1.5708 0 0" xyz="0 0 0"/>
      <geometry>
        <mesh filename="package://hexapod_description/meshes/leg_tibia.stl" scale="0.001 0.001 0.001"/>
      </geometry>
      <material name="red"/>
    </visual>
    <inertial>
      <origin rpy="1.5708 0 0" xyz="0.077796 -0.036156 0"/>
      <mass value="0.098"/>
      <inertia ixx="1.515e-4" ixy="1.52255e-7" ixz="-9.144e-5" iyx="1.52255e-7" iyy="2.328e-4" iyz="7.0753e-8" izx="-9.144e-5" izy="7.0753e-8" izz="1.159e-4"/>
    </inertial>
  </link>
  <joint name="leg3_tibia__leg3_rubber_tip" type="fixed">
    <parent link="leg3_tibia"/>
    <child link="leg3_rubber_tip"/>
  </joint>
  <link name="leg3_rubber_tip">
    <collision>
      <origin rpy="1.5708 0 0.3769938" xyz="0.136283 -0.133814 0"/>
      <geometry>
        <mesh filename="package://hexapod_description/meshes/leg_rubber_tip.stl" scale="0.001 0.001 0.001"/>
      </geometry>
    </collision>
    <visual>
      <origin rpy="1.5708 0 0.3769938" xyz="0.136283 -0.133814 0"/>
      <geometry>
        <mesh filename="package://hexapod_description/meshes/leg_rubber_tip.stl" scale="0.001 0.001 0.001"/>
      </geometry>
      <material name="red"/>
    </visual>
    <inertial>
      <origin rpy="1.5708 0 0.3769938" xyz="0.136283 -0.133814 0"/>
      <mass value="0.002"/>
      <inertia ixx="1.00584e-7" ixy="0" ixz="0" iyx="0" iyy="1.00579e-7" iyz="0" izx="0" izy="0" izz="1.05103e-7"/>
    </inertial>
  </link>
  <joint name="base_link__leg4_coxa" type="revolute">
    <axis xyz="0 0 1"/>
    <limit effort="2.8" lower="-1.5708" upper="1.5708" velocity="5.6548668"/>
    <origin rpy="0 3.14159 1.5708" xyz="-0.09850 0 0.021"/>
    <parent link="base_link"/>
    <child link="leg4_coxa"/>
  </joint>
  <link name="leg4_coxa">
    <collision>
      <origin rpy="0 3.14159 0" xyz="0 0 0"/>
      <geometry>
        <mesh filename="package://hexapod_description/meshes/leg_coxa_collision.stl" scale="0.001 0.001 0.001"/>
      </geometry>
    </collision>
    <visual>
      <origin rpy="0 3.14159 0" xyz="0 0 0"/>
      <geometry>
        <mesh filename="package://hexapod_description/meshes/leg_coxa.stl" scale="0.001 0.001 0.001"/>
      </geometry>
      <material name="red"/>
    </visual>
    <inertial>
      <origin rpy="0 3.14159 0" xyz="0 0.023937 0"/>
      <mass value="0.04"/>
      <inertia ixx="1.605e-5" ixy="-5.7988e-8" ixz="0" iyx="-5.7988e-8" iyy="2.012e-5" iyz="5.7639e-8" izx="0" izy="5.7639e-8" izz="1.605e-5"/>
    </inertial>
  </link>
  <joint name="leg4_coxa__leg4_femur" type="revolute">
    <axis xyz="0 0 1"/>
    <limit effort="2.8" lower="-1.5708" upper="1.5708" velocity="5.6548668"/>
    <origin rpy="-1.5708 0 1.5708" xyz="0 0.047868 0"/>
    <parent link="leg4_coxa"/>
    <child link="leg4_femur"/>
  </joint>
  <link name="leg4_femur">
    <collision>
      <origin rpy="-1.5708 0 0" xyz="0.0385 0 0"/>
      <geometry>
        <mesh filename="package://hexapod_description/meshes/leg_femur_collision.stl" scale="0.001 0.001 0.001"/>
      </geometry>
    </collision>
    <visual>
      <origin rpy="-1.5708 0 0" xyz="0.0385 0 0"/>
      <geometry>
        <mesh filename="package://hexapod_description/meshes/leg_femur.stl" scale="0.001 0.001 0.001"/>
      </geometry>
      <material name="red"/>
    </visual>
    <inertial>
      <origin rpy="0 0 1.5708" xyz="0.0385 0 0"/>
      <mass value="0.12"/>
      <inertia ixx="1.005e-4" ixy="0" ixz="0" iyx="0" iyy="2.532e-5" iyz="0" izx="0" izy="0" izz="1.071e-4"/>
    </inertial>
  </link>
  <joint name="leg4_femur__leg4_tibia" type="revolute">
    <axis xyz="0 0 1"/>
    <limit effort="2.8" lower="-1.5708" upper="1.5708" velocity="5.6548668"/>
    <origin rpy="0 0 0" xyz="0.077 0 0"/>
    <parent link="leg4_femur"/>
    <child link="leg4_tibia"/>
  </joint>
  <link name="leg4_tibia">
    <collision>
      <origin rpy="1.5708 0 0" xyz="0 0 0"/>
      <geometry>
        <mesh filename="package://hexapod_description/meshes/leg_tibia_collision.stl" scale="0.001 0.001 0.001"/>
      </geometry>
    </collision>
    <visual>
      <origin rpy="1.5708 0 0" xyz="0 0 0"/>
      <geometry>
        <mesh filename="package://hexapod_description/meshes/leg_tibia.stl" scale="0.001 0.001 0.001"/>
      </geometry>
      <material name="red"/>
    </visual>
    <inertial>
      <origin rpy="1.5708 0 0" xyz="0.077796 -0.036156 0"/>
      <mass value="0.098"/>
      <inertia ixx="1.515e-4" ixy="1.52255e-7" ixz="-9.144e-5" iyx="1.52255e-7" iyy="2.328e-4" iyz="7.0753e-8" izx="-9.144e-5" izy="7.0753e-8" izz="1.159e-4"/>
    </inertial>
  </link>
  <joint name="leg4_tibia__leg4_rubber_tip" type="fixed">
    <parent link="leg4_tibia"/>
    <child link="leg4_rubber_tip"/>
  </joint>
  <link name="leg4_rubber_tip">
    <collision>
      <origin rpy="1.5708 0 0.3769938" xyz="0.136283 -0.133814 0"/>
      <geometry>
        <mesh filename="package://hexapod_description/meshes/leg_rubber_tip.stl" scale="0.001 0.001 0.001"/>
      </geometry>
    </collision>
    <visual>
      <origin rpy="1.5708 0 0.3769938" xyz="0.136283 -0.133814 0"/>
      <geometry>
        <mesh filename="package://hexapod_description/meshes/leg_rubber_tip.stl" scale="0.001 0.001 0.001"/>
      </geometry>
      <material name="red"/>
    </visual>
    <inertial>
      <origin rpy="1.5708 0 0.3769938" xyz="0.136283 -0.133814 0"/>
      <mass value="0.002"/>
      <inertia ixx="1.00584e-7" ixy="0" ixz="0" iyx="0" iyy="1.00579e-7" iyz="0" izx="0" izy="0" izz="1.05103e-7"/>
    </inertial>
  </link>
  <joint name="base_link__leg5_coxa" type="revolute">
    <axis xyz="0 0 1"/>
    <limit effort="2.8" lower="-1.5708" upper="1.5708" velocity="5.6548668"/>
    <origin rpy="0 3.14159 -2.3562" xyz="0.072981 -0.109608 0.021"/>
    <parent link="base_link"/>
    <child link="leg5_coxa"/>
  </joint>
  <link name="leg5_coxa">
    <collision>
      <origin rpy="0 3.14159 0" xyz="0 0 0"/>
      <geometry>
        <mesh filename="package://hexapod_description/meshes/leg_coxa_collision.stl" scale="0.001 0.001 0.001"/>
      </geometry>
    </collision>
    <visual>
      <origin rpy="0 3.14159 0" xyz="0 0 0"/>
      <geometry>
        <mesh filename="package://hexapod_description/meshes/leg_coxa.stl" scale="0.001 0.001 0.001"/>
      </geometry>
      <material name="red"/>
    </visual>
    <inertial>
      <origin rpy="0 3.14159 0" xyz="0 0.023937 0"/>
      <mass value="0.04"/>
      <inertia ixx="1.605e-5" ixy="-5.7988e-8" ixz="0" iyx="-5.7988e-8" iyy="2.012e-5" iyz="5.7639e-8" izx="0" izy="5.7639e-8" izz="1.605e-5"/>
    </inertial>
  </link>
  <joint name="leg5_coxa__leg5_femur" type="revolute">
    <axis xyz="0 0 1"/>
    <limit effort="2.8" lower="-1.5708" upper="1.5708" velocity="5.6548668"/>
    <origin rpy="-1.5708 0 1.5708" xyz="0 0.047868 0"/>
    <parent link="leg5_coxa"/>
    <child link="leg5_femur"/>
  </joint>
  <link name="leg5_femur">
    <collision>
      <origin rpy="-1.5708 0 0" xyz="0.0385 0 0"/>
      <geometry>
        <mesh filename="package://hexapod_description/meshes/leg_femur_collision.stl" scale="0.001 0.001 0.001"/>
      </geometry>
    </collision>
    <visual>
      <origin rpy="-1.5708 0 0" xyz="0.0385 0 0"/>
      <geometry>
        <mesh filename="package://hexapod_description/meshes/leg_femur.stl" scale="0.001 0.001 0.001"/>
      </geometry>
      <material name="red"/>
    </visual>
    <inertial>
      <origin rpy="0 0 1.5708" xyz="0.0385 0 0"/>
      <mass value="0.12"/>
      <inertia ixx="1.005e-4" ixy="0" ixz="0" iyx="0" iyy="2.532e-5" iyz="0" izx="0" izy="0" izz="1.071e-4"/>
    </inertial>
  </link>
  <joint name="leg5_femur__leg5_tibia" type="revolute">
    <axis xyz="0 0 1"/>
    <limit effort="2.8" lower="-1.5708" upper="1.5708" velocity="5.6548668"/>
    <origin rpy="0 0 0" xyz="0.077 0 0"/>
    <parent link="leg5_femur"/>
    <child link="leg5_tibia"/>
  </joint>
  <link name="leg5_tibia">
    <collision>
      <origin rpy="1.5708 0 0" xyz="0 0 0"/>
      <geometry>
        <mesh filename="package://hexapod_description/meshes/leg_tibia_collision.stl" scale="0.001 0.001 0.001"/>
      </geometry>
    </collision>
    <visual>
      <origin rpy="1.5708 0 0" xyz="0 0 0"/>
      <geometry>
        <mesh filename="package://hexapod_description/meshes/leg_tibia.stl" scale="0.001 0.001 0.001"/>
      </geometry>
      <material name="red"/>
    </visual>
    <inertial>
      <origin rpy="1.5708 0 0" xyz="0.077796 -0.036156 0"/>
      <mass value="0.098"/>
      <inertia ixx="1.515e-4" ixy="1.52255e-7" ixz="-9.144e-5" iyx="1.52255e-7" iyy="2.328e-4" iyz="7.0753e-8" izx="-9.144e-5" izy="7.0753e-8" izz="1.159e-4"/>
    </inertial>
  </link>
  <joint name="leg5_tibia__leg5_rubber_tip" type="fixed">
    <parent link="leg5_tibia"/>
    <child link="leg5_rubber_tip"/>
  </joint>
  <link name="leg5_rubber_tip">
    <collision>
      <origin rpy="1.5708 0 0.3769938" xyz="0.136283 -0.133814 0"/>
      <geometry>
        <mesh filename="package://hexapod_description/meshes/leg_rubber_tip.stl" scale="0.001 0.001 0.001"/>
      </geometry>
    </collision>
    <visual>
      <origin rpy="1.5708 0 0.3769938" xyz="0.136283 -0.133814 0"/>
      <geometry>
        <mesh filename="package://hexapod_description/meshes/leg_rubber_tip.stl" scale="0.001 0.001 0.001"/>
      </geometry>
      <material name="red"/>
    </visual>
    <inertial>
      <origin rpy="1.5708 0 0.3769938" xyz="0.136283 -0.133814 0"/>
      <mass value="0.002"/>
      <inertia ixx="1.00584e-7" ixy="0" ixz="0" iyx="0" iyy="1.00579e-7" iyz="0" izx="0" izy="0" izz="1.05103e-7"/>
    </inertial>
  </link>
  <joint name="base_link__leg6_coxa" type="revolute">
    <axis xyz="0 0 1"/>
    <limit effort="2.8" lower="-1.5708" upper="1.5708" velocity="5.6548668"/>
    <origin rpy="0 3.14159 2.35622" xyz="-0.072981 -0.109608 0.021"/>
    <parent link="base_link"/>
    <child link="leg6_coxa"/>
  </joint>
  <link name="leg6_coxa">
    <collision>
      <origin rpy="0 3.14159 0" xyz="0 0 0"/>
      <geometry>
        <mesh filename="package://hexapod_description/meshes/leg_coxa_collision.stl" scale="0.001 0.001 0.001"/>
      </geometry>
    </collision>
    <visual>
      <origin rpy="0 3.14159 0" xyz="0 0 0"/>
      <geometry>
        <mesh filename="package://hexapod_description/meshes/leg_coxa.stl" scale="0.001 0.001 0.001"/>
      </geometry>
      <material name="red"/>
    </visual>
    <inertial>
      <origin rpy="0 3.14159 0" xyz="0 0.023937 0"/>
      <mass value="0.04"/>
      <inertia ixx="1.605e-5" ixy="-5.7988e-8" ixz="0" iyx="-5.7988e-8" iyy="2.012e-5" iyz="5.7639e-8" izx="0" izy="5.7639e-8" izz="1.605e-5"/>
    </inertial>
  </link>
  <joint name="leg6_coxa__leg6_femur" type="revolute">
    <axis xyz="0 0 1"/>
    <limit effort="2.8" lower="-1.5708" upper="1.5708" velocity="5.6548668"/>
    <origin rpy="-1.5708 0 1.5708" xyz="0 0.047868 0"/>
    <parent link="leg6_coxa"/>
    <child link="leg6_femur"/>
  </joint>
  <link name="leg6_femur">
    <collision>
      <origin rpy="-1.5708 0 0" xyz="0.0385 0 0"/>
      <geometry>
        <mesh filename="package://hexapod_description/meshes/leg_femur_collision.stl" scale="0.001 0.001 0.001"/>
      </geometry>
    </collision>
    <visual>
      <origin rpy="-1.5708 0 0" xyz="0.0385 0 0"/>
      <geometry>
        <mesh filename="package://hexapod_description/meshes/leg_femur.stl" scale="0.001 0.001 0.001"/>
      </geometry>
      <material name="red"/>
    </visual>
    <inertial>
      <origin rpy="0 0 1.5708" xyz="0.0385 0 0"/>
      <mass value="0.12"/>
      <inertia ixx="1.005e-4" ixy="0" ixz="0" iyx="0" iyy="2.532e-5" iyz="0" izx="0" izy="0" izz="1.071e-4"/>
    </inertial>
  </link>
  <joint name="leg6_femur__leg6_tibia" type="revolute">
    <axis xyz="0 0 1"/>
    <limit effort="2.8" lower="-1.5708" upper="1.5708" velocity="5.6548668"/>
    <origin rpy="0 0 0" xyz="0.077 0 0"/>
    <parent link="leg6_femur"/>
    <child link="leg6_tibia"/>
  </joint>
  <link name="leg6_tibia">
    <collision>
      <origin rpy="1.5708 0 0" xyz="0 0 0"/>
      <geometry>
        <mesh filename="package://hexapod_description/meshes/leg_tibia_collision.stl" scale="0.001 0.001 0.001"/>
      </geometry>
    </collision>
    <visual>
      <origin rpy="1.5708 0 0" xyz="0 0 0"/>
      <geometry>
        <mesh filename="package://hexapod_description/meshes/leg_tibia.stl" scale="0.001 0.001 0.001"/>
      </geometry>
      <material name="red"/>
    </visual>
    <inertial>
      <origin rpy="1.5708 0 0" xyz="0.077796 -0.036156 0"/>
      <mass value="0.098"/>
      <inertia ixx="1.515e-4" ixy="1.52255e-7" ixz="-9.144e-5" iyx="1.52255e-7" iyy="2.328e-4" iyz="7.0753e-8" izx="-9.144e-5" izy="7.0753e-8" izz="1.159e-4"/>
    </inertial>
  </link>
  <joint name="leg6_tibia__leg6_rubber_tip" type="fixed">
    <parent link="leg6_tibia"/>
    <child link="leg6_rubber_tip"/>
  </joint>
  <link name="leg6_rubber_tip">
    <collision>
      <origin rpy="1.5708 0 0.3769938" xyz="0.136283 -0.133814 0"/>
      <geometry>
        <mesh filename="package://hexapod_description/meshes/leg_rubber_tip.stl" scale="0.001 0.001 0.001"/>
      </geometry>
    </collision>
    <visual>
      <origin rpy="1.5708 0 0.3769938" xyz="0.136283 -0.133814 0"/>
      <geometry>
        <mesh filename="package://hexapod_description/meshes/leg_rubber_tip.stl" scale="0.001 0.001 0.001"/>
      </geometry>
      <material name="red"/>
    </visual>
    <inertial>
      <origin rpy="1.5708 0 0.3769938" xyz="0.136283 -0.133814 0"/>
      <mass value="0.002"/>
      <inertia ixx="1.00584e-7" ixy="0" ixz="0" iyx="0" iyy="1.00579e-7" iyz="0" izx="0" izy="0" izz="1.05103e-7"/>
    </inertial>
  </link>
  <transmission name="trans_base_link__leg1_coxa">
    <type>transmission_interface/SimpleTransmission</type>
    <joint name="base_link__leg1_coxa">
      <hardwareInterface>EffortJointInterface</hardwareInterface>
    </joint>
    <actuator name="motor_base_link__leg1_coxa">
      <hardwareInterface>EffortJointInterface</hardwareInterface>
      <mechanicalReduction>1</mechanicalReduction>
    </actuator>
  </transmission>
  <transmission name="trans_leg1_coxa__leg1_femur">
    <type>transmission_interface/SimpleTransmission</type>
    <joint name="leg1_coxa__leg1_femur">
      <hardwareInterface>EffortJointInterface</hardwareInterface>
    </joint>
    <actuator name="motor_leg1_coxa__leg1_femur">
      <hardwareInterface>EffortJointInterface</hardwareInterface>
      <mechanicalReduction>1</mechanicalReduction>
    </actuator>
  </transmission>
  <transmission name="trans_leg1_femur__leg1_tibia">
    <type>transmission_interface/SimpleTransmission</type>
    <joint name="leg1_femur__leg1_tibia">
      <hardwareInterface>EffortJointInterface</hardwareInterface>
    </joint>
    <actuator name="motor_leg1_femur__leg1_tibia">
      <hardwareInterface>EffortJointInterface</hardwareInterface>
      <mechanicalReduction>1</mechanicalReduction>
    </actuator>
  </transmission>
  <transmission name="trans_base_link__leg2_coxa">
    <type>transmission_interface/SimpleTransmission</type>
    <joint name="base_link__leg2_coxa">
      <hardwareInterface>EffortJointInterface</hardwareInterface>
    </joint>
    <actuator name="motor_base_link__leg2_coxa">
      <hardwareInterface>EffortJointInterface</hardwareInterface>
      <mechanicalReduction>1</mechanicalReduction>
    </actuator>
  </transmission>
  <transmission name="trans_leg2_coxa__leg2_femur">
    <type>transmission_interface/SimpleTransmission</type>
    <joint name="leg2_coxa__leg2_femur">
      <hardwareInterface>EffortJointInterface</hardwareInterface>
    </joint>
    <actuator name="motor_leg2_coxa__leg2_femur">
      <hardwareInterface>EffortJointInterface</hardwareInterface>
      <mechanicalReduction>1</mechanicalReduction>
    </actuator>
  </transmission>
  <transmission name="trans_leg2_femur__leg2_tibia">
    <type>transmission_interface/SimpleTransmission</type>
    <joint name="leg2_femur__leg2_tibia">
      <hardwareInterface>EffortJointInterface</hardwareInterface>
    </joint>
    <actuator name="motor_leg2_femur__leg2_tibia">
      <hardwareInterface>EffortJointInterface</hardwareInterface>
      <mechanicalReduction>1</mechanicalReduction>
    </actuator>
  </transmission>
  <transmission name="trans_base_link__leg3_coxa">
    <type>transmission_interface/SimpleTransmission</type>
    <joint name="base_link__leg3_coxa">
      <hardwareInterface>EffortJointInterface</hardwareInterface>
    </joint>
    <actuator name="motor_base_link__leg3_coxa">
      <hardwareInterface>EffortJointInterface</hardwareInterface>
      <mechanicalReduction>1</mechanicalReduction>
    </actuator>
  </transmission>
  <transmission name="trans_leg3_coxa__leg3_femur">
    <type>transmission_interface/SimpleTransmission</type>
    <joint name="leg3_coxa__leg3_femur">
      <hardwareInterface>EffortJointInterface</hardwareInterface>
    </joint>
    <actuator name="motor_leg3_coxa__leg3_femur">
      <hardwareInterface>EffortJointInterface</hardwareInterface>
      <mechanicalReduction>1</mechanicalReduction>
    </actuator>
  </transmission>
  <transmission name="trans_leg3_femur__leg3_tibia">
    <type>transmission_interface/SimpleTransmission</type>
    <joint name="leg3_femur__leg3_tibia">
      <hardwareInterface>EffortJointInterface</hardwareInterface>
    </joint>
    <actuator name="motor_leg3_femur__leg3_tibia">
      <hardwareInterface>EffortJointInterface</hardwareInterface>
      <mechanicalReduction>1</mechanicalReduction>
    </actuator>
  </transmission>
  <transmission name="trans_base_link__leg4_coxa">
    <type>transmission_interface/SimpleTransmission</type>
    <joint name="base_link__leg4_coxa">
      <hardwareInterface>EffortJointInterface</hardwareInterface>
    </joint>
    <actuator name="motor_base_link__leg4_coxa">
      <hardwareInterface>EffortJointInterface</hardwareInterface>
      <mechanicalReduction>1</mechanicalReduction>
    </actuator>
  </transmission>
  <transmission name="trans_leg4_coxa__leg4_femur">
    <type>transmission_interface/SimpleTransmission</type>
    <joint name="leg4_coxa__leg4_femur">
      <hardwareInterface>EffortJointInterface</hardwareInterface>
    </joint>
    <actuator name="motor_leg4_coxa__leg4_femur">
      <hardwareInterface>EffortJointInterface</hardwareInterface>
      <mechanicalReduction>1</mechanicalReduction>
    </actuator>
  </transmission>
  <transmission name="trans_leg4_femur__leg4_tibia">
    <type>transmission_interface/SimpleTransmission</type>
    <joint name="leg4_femur__leg4_tibia">
      <hardwareInterface>EffortJointInterface</hardwareInterface>
    </joint>
    <actuator name="motor_leg4_femur__leg4_tibia">
      <hardwareInterface>EffortJointInterface</hardwareInterface>
      <mechanicalReduction>1</mechanicalReduction>
    </actuator>
  </transmission>
  <transmission name="trans_base_link__leg5_coxa">
    <type>transmission_interface/SimpleTransmission</type>
    <joint name="base_link__leg5_coxa">
      <hardwareInterface>EffortJointInterface</hardwareInterface>
    </joint>
    <actuator name="motor_base_link__leg5_coxa">
      <hardwareInterface>EffortJointInterface</hardwareInterface>
      <mechanicalReduction>1</mechanicalReduction>
    </actuator>
  </transmission>
  <transmission name="trans_leg5_coxa__leg5_femur">
    <type>transmission_interface/SimpleTransmission</type>
    <joint name="leg5_coxa__leg5_femur">
      <hardwareInterface>EffortJointInterface</hardwareInterface>
    </joint>
    <actuator name="motor_leg5_coxa__leg5_femur">
      <hardwareInterface>EffortJointInterface</hardwareInterface>
      <mechanicalReduction>1</mechanicalReduction>
    </actuator>
  </transmission>
  <transmission name="trans_leg5_femur__leg5_tibia">
    <type>transmission_interface/SimpleTransmission</type>
    <joint name="leg5_femur__leg5_tibia">
      <hardwareInterface>EffortJointInterface</hardwareInterface>
    </joint>
    <actuator name="motor_leg5_femur__leg5_tibia">
      <hardwareInterface>EffortJointInterface</hardwareInterface>
      <mechanicalReduction>1</mechanicalReduction>
    </actuator>
  </transmission>
  <transmission name="trans_base_link__leg6_coxa">
    <type>transmission_interface/SimpleTransmission</type>
    <joint name="base_link__leg6_coxa">
      <hardwareInterface>EffortJointInterface</hardwareInterface>
    </joint>
    <actuator name="motor_base_link__leg6_coxa">
      <hardwareInterface>EffortJointInterface</hardwareInterface>
      <mechanicalReduction>1</mechanicalReduction>
    </actuator>
  </transmission>
  <transmission name="trans_leg6_coxa__leg6_femur">
    <type>transmission_interface/SimpleTransmission</type>
    <joint name="leg6_coxa__leg6_femur">
      <hardwareInterface>EffortJointInterface</hardwareInterface>
    </joint>
    <actuator name="motor_leg6_coxa__leg6_femur">
      <hardwareInterface>EffortJointInterface</hardwareInterface>
      <mechanicalReduction>1</mechanicalReduction>
    </actuator>
  </transmission>
  <transmission name="trans_leg6_femur__leg6_tibia">
    <type>transmission_interface/SimpleTransmission</type>
    <joint name="leg6_femur__leg6_tibia">
      <hardwareInterface>EffortJointInterface</hardwareInterface>
    </joint>
    <actuator name="motor_leg6_femur__leg6_tibia">
      <hardwareInterface>EffortJointInterface</hardwareInterface>
      <mechanicalReduction>1</mechanicalReduction>
    </actuator>
  </transmission>
</robot>

